Workbook

Sheet Summary
A1: Summary — all formulas
A3: Receipts
A4: Bank lines | B4: =COUNT(Receipts!$B$4:$B$600) -> 80
A5: Money in | B5: =SUMIF(Receipts!$B$4:$B$600,">0") -> 37328.24
A6: Money out (refunds / outflows) | B6: =SUMIF(Receipts!$B$4:$B$600,"<0") -> -409.5
A7: Money in — AUT-2025 | B7: =SUMIFS(Receipts!$B$4:$B$600,Receipts!$E$4:$E$600,"AUT-2025",Receipts!$B$4:$B$600,">0") -> 4125.25
A8: Money in — JAN-2026 | B8: =SUMIFS(Receipts!$B$4:$B$600,Receipts!$E$4:$E$600,"JAN-2026",Receipts!$B$4:$B$600,">0") -> 33202.99
A10: Allocation by tier (all terms)
A11: M — manual override [lines] | B11: =COUNTIF(Receipts!$I$4:$I$600,"M") -> 0
A12: M — manual override [£ in] | B12: =SUMIFS(Receipts!$B$4:$B$600,Receipts!$I$4:$I$600,"M",Receipts!$B$4:$B$600,">0") -> 0
A13: A — reference or verified payer alias [lines] | B13: =COUNTIF(Receipts!$I$4:$I$600,"A") -> 40
A14: A — reference or verified payer alias [£ in] | B14: =SUMIFS(Receipts!$B$4:$B$600,Receipts!$I$4:$I$600,"A",Receipts!$B$4:$B$600,">0") -> 19229.12
A15: B — unique surname in memo [lines] | B15: =COUNTIF(Receipts!$I$4:$I$600,"B") -> 29
A16: B — unique surname in memo [£ in] | B16: =SUMIFS(Receipts!$B$4:$B$600,Receipts!$I$4:$I$600,"B",Receipts!$B$4:$B$600,">0") -> 13453.87
A17: C — fuzzy / first name (review) [lines] | B17: =COUNTIF(Receipts!$I$4:$I$600,"C") -> 2
A18: C — fuzzy / first name (review) [£ in] | B18: =SUMIFS(Receipts!$B$4:$B$600,Receipts!$I$4:$I$600,"C",Receipts!$B$4:$B$600,">0") -> 694
A19: D — nothing usable or ambiguous (review) [lines] | B19: =COUNTIF(Receipts!$I$4:$I$600,"D") -> 6
A20: D — nothing usable or ambiguous (review) [£ in] | B20: =SUMIFS(Receipts!$B$4:$B$600,Receipts!$I$4:$I$600,"D",Receipts!$B$4:$B$600,">0") -> 2852.5
A21: X — reference contradicts memo (review) [lines] | B21: =COUNTIF(Receipts!$I$4:$I$600,"X") -> 3
A22: X — reference contradicts memo (review) [£ in] | B22: =SUMIFS(Receipts!$B$4:$B$600,Receipts!$I$4:$I$600,"X",Receipts!$B$4:$B$600,">0") -> 1098.75
A23: Lines allocated automatically | B23: =COUNTIF(Receipts!$H$4:$H$600,"yes") -> 69
A24: Share of lines allocated automatically | B24: =IF(COUNT(Receipts!$B$4:$B$600)=0,0,COUNTIF(Receipts!$H$4:$H$600,"yes")/COUNT(Receipts!$B$4:$B$600)) -> 0.8625
A25: JAN-2026 money in allocated | B25: =SUMIFS(Receipts!$B$4:$B$600,Receipts!$E$4:$E$600,"JAN-2026",Receipts!$H$4:$H$600,"yes",Receipts!$B$4:$B$600,">0") -> 29149.74
A26: JAN-2026 money in awaiting review | B26: =SUMIFS(Receipts!$B$4:$B$600,Receipts!$E$4:$E$600,"JAN-2026",Receipts!$H$4:$H$600,"",Receipts!$B$4:$B$600,">0") -> 4053.25
A27: Lines in Review queue | B27: =COUNTA(Review!$A$4:$A$600) -> 11
A29: Position — JAN-2026
A30: Expected income (rules) | B30: =SUM(Position!$E$5:$E$600) -> 36231.74
A31: Received (allocated) | B31: =SUM(Position!$F$5:$F$600) -> 29149.74
A32: Outstanding | B32: =SUMIF(Position!$G$5:$G$600,">0") -> 7491.5
A33: Families settled | B33: =COUNTIF(Position!$H$5:$H$600,"settled") -> 43
A34: Families part paid | B34: =COUNTIF(Position!$H$5:$H$600,"part paid") -> 5
A35: Families with nothing allocated | B35: =COUNTIF(Position!$H$5:$H$600,"unpaid") -> 11
A36: Families overpaid | B36: =COUNTIF(Position!$H$5:$H$600,"overpaid") -> 1
A37: Families flagged 'needs a look' | B37: =COUNTIF(Position!$M$5:$M$600,"?*") -> 19
A39: Rule check
A40: Children billed | B40: =COUNTIF(Children!$F$4:$F$500,"Enrolled") -> 93
A41: Invoices reproduced exactly by the fee rules | B41: =COUNTIFS(Children!$F$4:$F$500,"Enrolled",Children!$U$4:$U$500,"OK") -> 90
A43: Outstanding is overstated by whatever sits in Review and by any 2026 money tagged to AUT-2025. The AUT-2025 register is not loaded, so autumn has no position yet.

Sheet README
A1: Fee ledger — how it works
A2: Built from the pupil roster and the bank export. Health, guardian-contact and free-text pupil columns were deliberately not carried over.
A4: Where to look
A5: Position — the answer sheet. One row per family: what they owe, what came in, every receipt reference, whether it is settled. Colour-coded. Start here.
A6: Review — the only sheet that needs you. Receipts the engine would not allocate, with candidates and a reason. Decide, type the family ID into Receipts column F, re-run.
A7: Receipts — every bank line and what the engine did with it.
A8: Children / Families — the roster, and the fee each child should be charged. Difference and Check compare that with what the roster actually invoiced.
A9: Rates / Terms — the fee rules and the session counts. Change a number here and everything recalculates.
A10: Summary — headline figures.
A12: Colour key
A13: Blue text = typed in from a source file. Black = formula. Yellow fill = for you to fill in. Green = written by the engine.
A14: Green row / red row on Position = settled / owing. Amber = needs a look before you chase: a receipt sitting in Review, or money tagged to the wrong term.
... A32: Replace the bank export, run build_ledger.py then reconcile.py. Copy column F of Receipts and the alias column of Families first — manual decisions live in the workbook, not in the scripts.

Sheet Rates
A1: Fee rules — inputs (blue). Source: charity price list, January 2026 (photo supplied by user).
A3: Item | B3: Basis | C3: £ per session / per item | D3: Source / note
A4: Saturday school — 1 child | B4: per family per session | C4: 19.5 | D4: £195 per 10 sessions
A5: Saturday school — 2 siblings | B5: per family per session | C5: 34.5 | D5: £345 per 10 sessions
A6: Saturday school — 3 siblings | B6: per family per session | C6: 46 | D6: £460 per 10 sessions
A7: Saturday school — 4 siblings | B7: per family per session | C7: 57.1 | D7: £571 per 10 sessions
A9: Wednesday class — per child | B9: per child per session | C9: 16 | D9: £160 per 10 sessions; no sibling tier listed
A11: Registration fee | B11: per child, one-off at first registration | C11: 25 | D11: Price list says per family for Wednesday — treated per child here (one Wednesday child only)
A12: Supplies / annual membership | B12: per child per year | C12: 25 | D12: Price list
A14: Trial — Saturday, 1 child | B14: information only, not used in formulas | C14: 19.5 | D14: £34.50 / £46 / £57 for 2 / 3 / 4 siblings
A15: Trial — Wednesday | B15: information only, not used in formulas | C15: 16

Sheet Terms
A1: Invoicing terms — inputs (blue). Add a row per new term; the register for each term goes in Invoices.
A3: Term ID | B3: Description | C3: Saturday sessions | D3: Wednesday sessions | E3: Invoice series | F3: Register loaded? | G3: Receipts window from | H3: Receipts window to | I3: Note
A4: AUT-2025 | B4: Autumn 2025 (Sep–Dec) | C4: 11 | D4: 11 | E4: 2025-5xx / 2025-6xx | F4: No | G4: 45870 | H4: 46005 | I4: Sessions inferred from receipts (£214.50 = 11 × £19.50). Invoice register not supplied — add it to allocate autumn receipts.
A5: JAN-2026 | B5: Term starting January 2026 | C5: 21 | D5: 20 | E5: 2026-xxx | F5: Yes | G5: 46006 | H5: 46265 | I5: 21 = £409.50 ÷ £19.50. Wednesday 20 = £320 ÷ £16 (single club invoice). Confirm both with the office.

Sheet Families
A1: Families — stable key. One family can have several invoice numbers over time; the family ID never changes.
A3: Family ID | B3: Family surname(s) | C3: Children on roster | D3: Children billed (JAN-2026) | E3: Invoice no(s) JAN-2026 | F3: Bank payer alias (fill in; separate with ;) | G3: Payer names seen with a verified reference (engine) | H3: Note
A4: FAM-001 | B4: ABARCA | C4: =COUNTIF(Children!$B$4:$B$500,$A4) -> 1 | D4: =COUNTIFS(Children!$B$4:$B$500,$A4,Children!$F$4:$F$500,"Enrolled") -> 1 | E4: 2026-004 | G4: INGRID ABARCA
A5: FAM-002 | B5: ACHTERBERG | C5: =COUNTIF(Children!$B$4:$B$500,$A5) -> 1 | D5: =COUNTIFS(Children!$B$4:$B$500,$A5,Children!$F$4:$F$500,"Enrolled") -> 1 | E5: 2026-052
A6: FAM-003 | B6: ACHTERBERG-MARCHETTI | C6: =COUNTIF(Children!$B$4:$B$500,$A6) -> 1 | D6: =COUNTIFS(Children!$B$4:$B$500,$A6,Children!$F$4:$F$500,"Enrolled") -> 1 | E6: 2026-001 | G6: ADRIEN ACHTERBERG-MARCH
A7: FAM-004 | B7: ASHWORTH | C7: =COUNTIF(Children!$B$4:$B$500,$A7) -> 1 | D7: =COUNTIFS(Children!$B$4:$B$500,$A7,Children!$F$4:$F$500,"Enrolled") -> 1 | E7: 2026-005
A8: FAM-005 | B8: AUCLAIR | C8: =COUNTIF(Children!$B$4:$B$500,$A8) -> 2 | D8: =COUNTIFS(Children!$B$4:$B$500,$A8,Children!$F$4:$F$500,"Enrolled") -> 2 | E8: 2026-054 | G8: DERMOT AUCLAIR
A9: FAM-006 | B9: BAPTISTE | C9: =COUNTIF(Children!$B$4:$B$500,$A9) -> 2 | D9: =COUNTIFS(Children!$B$4:$B$500,$A9,Children!$F$4:$F$500,"Enrolled") -> 2 | E9: 2026-006 | G9: INGRID BAPTISTE
A10: FAM-007 | B10: BEAUCHAMP | C10: =COUNTIF(Children!$B$4:$B$500,$A10) -> 1 | D10: =COUNTIFS(Children!$B$4:$B$500,$A10,Children!$F$4:$F$500,"Enrolled") -> 1 | E10: 2026-007
A11: FAM-008 | B11: BELHADJ | C11: =COUNTIF(Children!$B$4:$B$500,$A11) -> 2 | D11: =COUNTIFS(Children!$B$4:$B$500,$A11,Children!$F$4:$F$500,"Enrolled") -> 2 | E11: 2026-008 | G11: GENEVIEVE BELHADJ | H11: invoice number shared with another family — 2026-008
A12: FAM-009 | B12: BELHADJ-TREVELYAN | C12: =COUNTIF(Children!$B$4:$B$500,$A12) -> 1 | D12: =COUNTIFS(Children!$B$4:$B$500,$A12,Children!$F$4:$F$500,"Enrolled") -> 1 | E12: 2026-002
A13: FAM-010 | B13: BERGQVIST | C13: =COUNTIF(Children!$B$4:$B$500,$A13) -> 2 | D13: =COUNTIFS(Children!$B$4:$B$500,$A13,Children!$F$4:$F$500,"Enrolled") -> 2 | E13: 2026-009 | G13: STEFAN BERGQVIST
A14: FAM-011 | B14: BLOMFIELD | C14: =COUNTIF(Children!$B$4:$B$500,$A14) -> 1 | D14: =COUNTIFS(Children!$B$4:$B$500,$A14,Children!$F$4:$F$500,"Enrolled") -> 1 | E14: 2026-010
A15: FAM-012 | B15: BOSANQUET | C15: =COUNTIF(Children!$B$4:$B$500,$A15) -> 2 | D15: =COUNTIFS(Children!$B$4:$B$500,$A15,Children!$F$4:$F$500,"Enrolled") -> 2 | E15: 2026-053 | G15: STEFAN BOSANQUET
A16: FAM-013 | B16: BRANNIGAN | C16: =COUNTIF(Children!$B$4:$B$500,$A16) -> 4 | D16: =COUNTIFS(Children!$B$4:$B$500,$A16,Children!$F$4:$F$500,"Enrolled") -> 4 | E16: 2026-055
A17: FAM-014 | B17: CARDOSO | C17: =COUNTIF(Children!$B$4:$B$500,$A17) -> 3 | D17: =COUNTIFS(Children!$B$4:$B$500,$A17,Children!$F$4:$F$500,"Enrolled") -> 3 | E17: 2026-011
A18: FAM-015 | B18: CASTELLANE | C18: =COUNTIF(Children!$B$4:$B$500,$A18) -> 2 | D18: =COUNTIFS(Children!$B$4:$B$500,$A18,Children!$F$4:$F$500,"Enrolled") -> 2 | E18: 2026-056 | G18: KATRIN CASTELLANE
A19: FAM-016 | B19: CHIDOZIE | C19: =COUNTIF(Children!$B$4:$B$500,$A19) -> 1 | D19: =COUNTIFS(Children!$B$4:$B$500,$A19,Children!$F$4:$F$500,"Enrolled") -> 0
A20: FAM-017 | B20: CHIDOZIE | C20: =COUNTIF(Children!$B$4:$B$500,$A20) -> 2 | D20: =COUNTIFS(Children!$B$4:$B$500,$A20,Children!$F$4:$F$500,"Enrolled") -> 2 | E20: 2026-012
A21: FAM-018 | B21: COMEAU | C21: =COUNTIF(Children!$B$4:$B$500,$A21) -> 1 | D21: =COUNTIFS(Children!$B$4:$B$500,$A21,Children!$F$4:$F$500,"Enrolled") -> 1 | E21: 2026-013 | G21: ZORA COMEAU
A22: FAM-019 | B22: DARRIEUSSECQ | C22: =COUNTIF(Children!$B$4:$B$500,$A22) -> 1 | D22: =COUNTIFS(Children!$B$4:$B$500,$A22,Children!$F$4:$F$500,"Enrolled") -> 1 | E22: 2026-014 | G22: FERGUS DARRIEUSSECQ
A23: FAM-020 | B23: DELACROIX | C23: =COUNTIF(Children!$B$4:$B$500,$A23) -> 3 | D23: =COUNTIFS(Children!$B$4:$B$500,$A23,Children!$F$4:$F$500,"Enrolled") -> 3 | E23: 2026-015 | G23: BETTINA DELACROIX
A24: FAM-021 | B24: DUPLANTIER | C24: =COUNTIF(Children!$B$4:$B$500,$A24) -> 1 | D24: =COUNTIFS(Children!$B$4:$B$500,$A24,Children!$F$4:$F$500,"Enrolled") -> 1 | E24: 2026-016
A25: FAM-022 | B25: DZIEDZIC | C25: =COUNTIF(Children!$B$4:$B$500,$A25) -> 1 | D25: =COUNTIFS(Children!$B$4:$B$500,$A25,Children!$F$4:$F$500,"Enrolled") -> 1 | E25: 2026-057 | G25: NILS DZIEDZIC
A26: FAM-023 | B26: ERIKSEN | C26: =COUNTIF(Children!$B$4:$B$500,$A26) -> 1 | D26: =COUNTIFS(Children!$B$4:$B$500,$A26,Children!$F$4:$F$500,"Enrolled") -> 1 | E26: 2026-017 | G26: INGRID ERIKSEN
A27: FAM-024 | B27: FALZON | C27: =COUNTIF(Children!$B$4:$B$500,$A27) -> 1 | D27: =COUNTIFS(Children!$B$4:$B$500,$A27,Children!$F$4:$F$500,"Enrolled") -> 1 | E27: 2026-018 | G27: VERA FALZON
A28: FAM-025 | B28: FERREIRO | C28: =COUNTIF(Children!$B$4:$B$500,$A28) -> 1 | D28: =COUNTIFS(Children!$B$4:$B$500,$A28,Children!$F$4:$F$500,"Enrolled") -> 1 | E28: 2026-058
A29: FAM-026 | B29: FITZHUGH | C29: =COUNTIF(Children!$B$4:$B$500,$A29) -> 1 | D29: =COUNTIFS(Children!$B$4:$B$500,$A29,Children!$F$4:$F$500,"Enrolled") -> 1 | E29: 2026-019 | G29: TOVE FITZHUGH
A30: FAM-027 | B30: GAILLARD | C30: =COUNTIF(Children!$B$4:$B$500,$A30) -> 1 | D30: =COUNTIFS(Children!$B$4:$B$500,$A30,Children!$F$4:$F$500,"Enrolled") -> 1 | E30: 2026-020
A31: FAM-028 | B31: GRIMALDSEN | C31: =COUNTIF(Children!$B$4:$B$500,$A31) -> 3 | D31: =COUNTIFS(Children!$B$4:$B$500,$A31,Children!$F$4:$F$500,"Enrolled") -> 3 | E31: 2026-059
A32: FAM-029 | B32: GRYNBERG | C32: =COUNTIF(Children!$B$4:$B$500,$A32) -> 1 | D32: =COUNTIFS(Children!$B$4:$B$500,$A32,Children!$F$4:$F$500,"Enrolled") -> 1 | E32: 2026-021
A33: FAM-030 | B33: HALVORSEN | C33: =COUNTIF(Children!$B$4:$B$500,$A33) -> 4 | D33: =COUNTIFS(Children!$B$4:$B$500,$A33,Children!$F$4:$F$500,"Enrolled") -> 4 | E33: 2026-022 | G33: PASCAL HALVORSEN
A34: FAM-031 | B34: HASANOVIC | C34: =COUNTIF(Children!$B$4:$B$500,$A34) -> 1 | D34: =COUNTIFS(Children!$B$4:$B$500,$A34,Children!$F$4:$F$500,"Enrolled") -> 1 | E34: 2026-060
A35: FAM-032 | B35: HOLLINGWORTH | C35: =COUNTIF(Children!$B$4:$B$500,$A35) -> 1 | D35: =COUNTIFS(Children!$B$4:$B$500,$A35,Children!$F$4:$F$500,"Enrolled") -> 1 | E35: 2026-023
A36: FAM-033 | B36: IBARRA | C36: =COUNTIF(Children!$B$4:$B$500,$A36) -> 1 | D36: =COUNTIFS(Children!$B$4:$B$500,$A36,Children!$F$4:$F$500,"Enrolled") -> 1 | E36: 2026-024 | G36: PASCAL IBARRA
A37: FAM-034 | B37: JANKOWSKI | C37: =COUNTIF(Children!$B$4:$B$500,$A37) -> 1 | D37: =COUNTIFS(Children!$B$4:$B$500,$A37,Children!$F$4:$F$500,"Enrolled") -> 1 | E37: 2026-025 | G37: JEROME JANKOWSKI
A38: FAM-035 | B38: KACZMAREK | C38: =COUNTIF(Children!$B$4:$B$500,$A38) -> 3 | D38: =COUNTIFS(Children!$B$4:$B$500,$A38,Children!$F$4:$F$500,"Enrolled") -> 3 | E38: 2026-026 | G38: ELODIE KACZMAREK
A39: FAM-036 | B39: KILBRIDE | C39: =COUNTIF(Children!$B$4:$B$500,$A39) -> 3 | D39: =COUNTIFS(Children!$B$4:$B$500,$A39,Children!$F$4:$F$500,"Enrolled") -> 3 | E39: 2026-027 | G39: GENEVIEVE KILBRIDE
A40: FAM-037 | B40: LACHAPELLE | C40: =COUNTIF(Children!$B$4:$B$500,$A40) -> 2 | D40: =COUNTIFS(Children!$B$4:$B$500,$A40,Children!$F$4:$F$500,"Enrolled") -> 2 | E40: 2026-028 | G40: CAMILLE LACHAPELLE
A41: FAM-038 | B41: LINDQVIST | C41: =COUNTIF(Children!$B$4:$B$500,$A41) -> 2 | D41: =COUNTIFS(Children!$B$4:$B$500,$A41,Children!$F$4:$F$500,"Enrolled") -> 2 | E41: 2026-029
...

Sheet Children
A1: Children — facts per child (blue) drive the expected fee (black). 'Check' must be OK; anything else is an invoice that does not follow the rules.
A3: Child ID | B3: Family ID | C3: Surname | D3: First name | E3: Class | F3: Status | G3: Term | H3: Invoice no (roster) | I3: Sessions | J3: Sessions override | K3: Siblings billed | L3: Rate per session | M3: Tuition | N3: Discount | O3: Add-ons charged | P3: Reg fee | Q3: Supplies | R3: Expected total | S3: Invoiced on roster | T3: Difference | U3: Check | V3: Note
A4: CH-001 | B4: FAM-001 | C4: ABARCA | D4: Lorcan | E4: Saturday | F4: Enrolled | G4: JAN-2026 | H4: 2026-004 | I4: =IF($J4<>"",$J4,IF($E4="Wednesday",INDEX(Terms!$D$4:$D$5,MATCH($G4,Terms!$A$4:$A$5,0)),INDEX(Terms!$C$4:$C$5,MATCH($G4,Terms!$A$4:$A$5,0)))) -> 21 | K4: =COUNTIFS($B$4:$B$500,$B4,$F$4:$F$500,"Enrolled") -> 1 | L4: =IF($F4<>"Enrolled",0,IF($K4=0,0,IF($E4="Wednesday",Rates!$C$9,INDEX(Rates!$C$4:$C$7,MIN($K4,4))/$K4))) -> 19.5 | M4: =ROUND($L4*$I4,2) -> 409.5 | N4: 0 | P4: =IF(ISNUMBER(SEARCH("reg",$O4)),Rates!$C$11,0) -> 0 | Q4: =IF(ISNUMBER(SEARCH("supplies",$O4)),Rates!$C$12,0) -> 0 | R4: =$M4-$N4+$P4+$Q4 -> 409.5 | S4: 409.5 | T4: =ROUND($R4-$S4,2) -> 0 | U4: =IF(ABS($T4)<0.02,"OK","CHECK") -> OK | V4: roster PAID: paid
A5: CH-002 | B5: FAM-002 | C5: ACHTERBERG | D5: Eleni | E5: Saturday | F5: Enrolled | G5: JAN-2026 | H5: 2026-052 | I5: =IF($J5<>"",$J5,IF($E5="Wednesday",INDEX(Terms!$D$4:$D$5,MATCH($G5,Terms!$A$4:$A$5,0)),INDEX(Terms!$C$4:$C$5,MATCH($G5,Terms!$A$4:$A$5,0)))) -> 21 | K5: =COUNTIFS($B$4:$B$500,$B5,$F$4:$F$500,"Enrolled") -> 1 | L5: =IF($F5<>"Enrolled",0,IF($K5=0,0,IF($E5="Wednesday",Rates!$C$9,INDEX(Rates!$C$4:$C$7,MIN($K5,4))/$K5))) -> 19.5 | M5: =ROUND($L5*$I5,2) -> 409.5 | N5: 0 | O5: supplies | P5: =IF(ISNUMBER(SEARCH("reg",$O5)),Rates!$C$11,0) -> 0 | Q5: =IF(ISNUMBER(SEARCH("supplies",$O5)),Rates!$C$12,0) -> 25 | R5: =$M5-$N5+$P5+$Q5 -> 434.5 | S5: 434.5 | T5: =ROUND($R5-$S5,2) -> 0 | U5: =IF(ABS($T5)<0.02,"OK","CHECK") -> OK | V5: roster PAID: paid
A6: CH-003 | B6: FAM-003 | C6: ACHTERBERG-MARCHETTI | D6: Leocadie | E6: Saturday | F6: Enrolled | G6: JAN-2026 | H6: 2026-001 | I6: =IF($J6<>"",$J6,IF($E6="Wednesday",INDEX(Terms!$D$4:$D$5,MATCH($G6,Terms!$A$4:$A$5,0)),INDEX(Terms!$C$4:$C$5,MATCH($G6,Terms!$A$4:$A$5,0)))) -> 21 | K6: =COUNTIFS($B$4:$B$500,$B6,$F$4:$F$500,"Enrolled") -> 1 | L6: =IF($F6<>"Enrolled",0,IF($K6=0,0,IF($E6="Wednesday",Rates!$C$9,INDEX(Rates!$C$4:$C$7,MIN($K6,4))/$K6))) -> 19.5 | M6: =ROUND($L6*$I6,2) -> 409.5 | N6: 0 | O6: supplies | P6: =IF(ISNUMBER(SEARCH("reg",$O6)),Rates!$C$11,0) -> 0 | Q6: =IF(ISNUMBER(SEARCH("supplies",$O6)),Rates!$C$12,0) -> 25 | R6: =$M6-$N6+$P6+$Q6 -> 434.5 | S6: 434.5 | T6: =ROUND($R6-$S6,2) -> 0 | U6: =IF(ABS($T6)<0.02,"OK","CHECK") -> OK | V6: roster PAID: paid
A7: CH-004 | B7: FAM-004 | C7: ASHWORTH | D7: Maelys | E7: Saturday | F7: Enrolled | G7: JAN-2026 | H7: 2026-005 | I7: =IF($J7<>"",$J7,IF($E7="Wednesday",INDEX(Terms!$D$4:$D$5,MATCH($G7,Terms!$A$4:$A$5,0)),INDEX(Terms!$C$4:$C$5,MATCH($G7,Terms!$A$4:$A$5,0)))) -> 21 | K7: =COUNTIFS($B$4:$B$500,$B7,$F$4:$F$500,"Enrolled") -> 1 | L7: =IF($F7<>"Enrolled",0,IF($K7=0,0,IF($E7="Wednesday",Rates!$C$9,INDEX(Rates!$C$4:$C$7,MIN($K7,4))/$K7))) -> 19.5 | M7: =ROUND($L7*$I7,2) -> 409.5 | N7: 0 | O7: supplies | P7: =IF(ISNUMBER(SEARCH("reg",$O7)),Rates!$C$11,0) -> 0 | Q7: =IF(ISNUMBER(SEARCH("supplies",$O7)),Rates!$C$12,0) -> 25 | R7: =$M7-$N7+$P7+$Q7 -> 434.5 | S7: 434.5 | T7: =ROUND($R7-$S7,2) -> 0 | U7: =IF(ABS($T7)<0.02,"OK","CHECK") -> OK | V7: roster PAID: paid
A8: CH-005 | B8: FAM-005 | C8: AUCLAIR | D8: Halima | E8: Saturday | F8: Enrolled | G8: JAN-2026 | H8: 2026-054 | I8: =IF($J8<>"",$J8,IF($E8="Wednesday",INDEX(Terms!$D$4:$D$5,MATCH($G8,Terms!$A$4:$A$5,0)),INDEX(Terms!$C$4:$C$5,MATCH($G8,Terms!$A$4:$A$5,0)))) -> 21 | K8: =COUNTIFS($B$4:$B$500,$B8,$F$4:$F$500,"Enrolled") -> 2 | L8: =IF($F8<>"Enrolled",0,IF($K8=0,0,IF($E8="Wednesday",Rates!$C$9,INDEX(Rates!$C$4:$C$7,MIN($K8,4))/$K8))) -> 17.25 | M8: =ROUND($L8*$I8,2) -> 362.25 | N8: 0 | O8: supplies | P8: =IF(ISNUMBER(SEARCH("reg",$O8)),Rates!$C$11,0) -> 0 | Q8: =IF(ISNUMBER(SEARCH("supplies",$O8)),Rates!$C$12,0) -> 25 | R8: =$M8-$N8+$P8+$Q8 -> 387.25 | S8: 387.25 | T8: =ROUND($R8-$S8,2) -> 0 | U8: =IF(ABS($T8)<0.02,"OK","CHECK") -> OK
A9: CH-006 | B9: FAM-005 | C9: AUCLAIR | D9: Xanthe | E9: Saturday | F9: Enrolled | G9: JAN-2026 | H9: 2026-054a | I9: =IF($J9<>"",$J9,IF($E9="Wednesday",INDEX(Terms!$D$4:$D$5,MATCH($G9,Terms!$A$4:$A$5,0)),INDEX(Terms!$C$4:$C$5,MATCH($G9,Terms!$A$4:$A$5,0)))) -> 21 | K9: =COUNTIFS($B$4:$B$500,$B9,$F$4:$F$500,"Enrolled") -> 2 | L9: =IF($F9<>"Enrolled",0,IF($K9=0,0,IF($E9="Wednesday",Rates!$C$9,INDEX(Rates!$C$4:$C$7,MIN($K9,4))/$K9))) -> 17.25 | M9: =ROUND($L9*$I9,2) -> 362.25 | N9: 0 | P9: =IF(ISNUMBER(SEARCH("reg",$O9)),Rates!$C$11,0) -> 0 | Q9: =IF(ISNUMBER(SEARCH("supplies",$O9)),Rates!$C$12,0) -> 0 | R9: =$M9-$N9+$P9+$Q9 -> 362.25 | S9: 362.25 | T9: =ROUND($R9-$S9,2) -> 0 | U9: =IF(ABS($T9)<0.02,"OK","CHECK") -> OK
A10: CH-007 | B10: FAM-006 | C10: BAPTISTE | D10: Kaia | E10: Saturday | F10: Enrolled | G10: JAN-2026 | H10: 2026-006 | I10: =IF($J10<>"",$J10,IF($E10="Wednesday",INDEX(Terms!$D$4:$D$5,MATCH($G10,Terms!$A$4:$A$5,0)),INDEX(Terms!$C$4:$C$5,MATCH($G10,Terms!$A$4:$A$5,0)))) -> 21 | K10: =COUNTIFS($B$4:$B$500,$B10,$F$4:$F$500,"Enrolled") -> 2 | L10: =IF($F10<>"Enrolled",0,IF($K10=0,0,IF($E10="Wednesday",Rates!$C$9,INDEX(Rates!$C$4:$C$7,MIN($K10,4))/$K10))) -> 17.25 | M10: =ROUND($L10*$I10,2) -> 362.25 | N10: 0 | O10: supplies | P10: =IF(ISNUMBER(SEARCH("reg",$O10)),Rates!$C$11,0) -> 0 | Q10: =IF(ISNUMBER(SEARCH("supplies",$O10)),Rates!$C$12,0) -> 25 | R10: =$M10-$N10+$P10+$Q10 -> 387.25 | S10: 387.25 | T10: =ROUND($R10-$S10,2) -> 0 | U10: =IF(ABS($T10)<0.02,"OK","CHECK") -> OK
A11: CH-008 | B11: FAM-006 | C11: BAPTISTE | D11: Piero | E11: Saturday | F11: Enrolled | G11: JAN-2026 | H11: 2026-006a | I11: =IF($J11<>"",$J11,IF($E11="Wednesday",INDEX(Terms!$D$4:$D$5,MATCH($G11,Terms!$A$4:$A$5,0)),INDEX(Terms!$C$4:$C$5,MATCH($G11,Terms!$A$4:$A$5,0)))) -> 21 | K11: =COUNTIFS($B$4:$B$500,$B11,$F$4:$F$500,"Enrolled") -> 2 | L11: =IF($F11<>"Enrolled",0,IF($K11=0,0,IF($E11="Wednesday",Rates!$C$9,INDEX(Rates!$C$4:$C$7,MIN($K11,4))/$K11))) -> 17.25 | M11: =ROUND($L11*$I11,2) -> 362.25 | N11: 0 | O11: supplies | P11: =IF(ISNUMBER(SEARCH("reg",$O11)),Rates!$C$11,0) -> 0 | Q11: =IF(ISNUMBER(SEARCH("supplies",$O11)),Rates!$C$12,0) -> 25 | R11: =$M11-$N11+$P11+$Q11 -> 387.25 | S11: 387.25 | T11: =ROUND($R11-$S11,2) -> 0 | U11: =IF(ABS($T11)<0.02,"OK","CHECK") -> OK | V11: roster PAID: paid
A12: CH-009 | B12: FAM-007 | C12: BEAUCHAMP | D12: Anselm | E12: Saturday | F12: Enrolled | G12: JAN-2026 | H12: 2026-007 | I12: =IF($J12<>"",$J12,IF($E12="Wednesday",INDEX(Terms!$D$4:$D$5,MATCH($G12,Terms!$A$4:$A$5,0)),INDEX(Terms!$C$4:$C$5,MATCH($G12,Terms!$A$4:$A$5,0)))) -> 21 | K12: =COUNTIFS($B$4:$B$500,$B12,$F$4:$F$500,"Enrolled") -> 1 | L12: =IF($F12<>"Enrolled",0,IF($K12=0,0,IF($E12="Wednesday",Rates!$C$9,INDEX(Rates!$C$4:$C$7,MIN($K12,4))/$K12))) -> 19.5 | M12: =ROUND($L12*$I12,2) -> 409.5 | N12: 0 | O12: supplies | P12: =IF(ISNUMBER(SEARCH("reg",$O12)),Rates!$C$11,0) -> 0 | Q12: =IF(ISNUMBER(SEARCH("supplies",$O12)),Rates!$C$12,0) -> 25 | R12: =$M12-$N12+$P12+$Q12 -> 434.5 | S12: 434.5 | T12: =ROUND($R12-$S12,2) -> 0 | U12: =IF(ABS($T12)<0.02,"OK","CHECK") -> OK | V12: roster PAID: part paid
A13: CH-010 | B13: FAM-008 | C13: BELHADJ | D13: Celestine | E13: Saturday | F13: Enrolled | G13: JAN-2026 | H13: 2026-008 | I13: =IF($J13<>"",$J13,IF($E13="Wednesday",INDEX(Terms!$D$4:$D$5,MATCH($G13,Terms!$A$4:$A$5,0)),INDEX(Terms!$C$4:$C$5,MATCH($G13,Terms!$A$4:$A$5,0)))) -> 21 | K13: =COUNTIFS($B$4:$B$500,$B13,$F$4:$F$500,"Enrolled") -> 2 | L13: =IF($F13<>"Enrolled",0,IF($K13=0,0,IF($E13="Wednesday",Rates!$C$9,INDEX(Rates!$C$4:$C$7,MIN($K13,4))/$K13))) -> 17.25 | M13: =ROUND($L13*$I13,2) -> 362.25 | N13: 0 | O13: supplies | P13: =IF(ISNUMBER(SEARCH("reg",$O13)),Rates!$C$11,0) -> 0 | Q13: =IF(ISNUMBER(SEARCH("supplies",$O13)),Rates!$C$12,0) -> 25 | R13: =$M13-$N13+$P13+$Q13 -> 387.25 | S13: 387.25 | T13: =ROUND($R13-$S13,2) -> 0 | U13: =IF(ABS($T13)<0.02,"OK","CHECK") -> OK
A14: CH-011 | B14: FAM-008 | C14: BELHADJ | D14: Gaspard | E14: Saturday | F14: Enrolled | G14: JAN-2026 | H14: 2026-008a | I14: =IF($J14<>"",$J14,IF($E14="Wednesday",INDEX(Terms!$D$4:$D$5,MATCH($G14,Terms!$A$4:$A$5,0)),INDEX(Terms!$C$4:$C$5,MATCH($G14,Terms!$A$4:$A$5,0)))) -> 21 | K14: =COUNTIFS($B$4:$B$500,$B14,$F$4:$F$500,"Enrolled") -> 2 | L14: =IF($F14<>"Enrolled",0,IF($K14=0,0,IF($E14="Wednesday",Rates!$C$9,INDEX(Rates!$C$4:$C$7,MIN($K14,4))/$K14))) -> 17.25 | M14: =ROUND($L14*$I14,2) -> 362.25 | N14: 0 | O14: supplies | P14: =IF(ISNUMBER(SEARCH("reg",$O14)),Rates!$C$11,0) -> 0 | Q14: =IF(ISNUMBER(SEARCH("supplies",$O14)),Rates!$C$12,0) -> 25 | R14: =$M14-$N14+$P14+$Q14 -> 387.25 | S14: 387.25 | T14: =ROUND($R14-$S14,2) -> 0 | U14: =IF(ABS($T14)<0.02,"OK","CHECK") -> OK | V14: roster PAID: paid
A15: CH-012 | B15: FAM-009 | C15: BELHADJ-TREVELYAN | D15: Beatriz | E15: Saturday | F15: Enrolled | G15: JAN-2026 | H15: 2026-002 | I15: =IF($J15<>"",$J15,IF($E15="Wednesday",INDEX(Terms!$D$4:$D$5,MATCH($G15,Terms!$A$4:$A$5,0)),INDEX(Terms!$C$4:$C$5,MATCH($G15,Terms!$A$4:$A$5,0)))) -> 21 | K15: =COUNTIFS($B$4:$B$500,$B15,$F$4:$F$500,"Enrolled") -> 1 | L15: =IF($F15<>"Enrolled",0,IF($K15=0,0,IF($E15="Wednesday",Rates!$C$9,INDEX(Rates!$C$4:$C$7,MIN($K15,4))/$K15))) -> 19.5 | M15: =ROUND($L15*$I15,2) -> 409.5 | N15: 0 | O15: supplies | P15: =IF(ISNUMBER(SEARCH("reg",$O15)),Rates!$C$11,0) -> 0 | Q15: =IF(ISNUMBER(SEARCH("supplies",$O15)),Rates!$C$12,0) -> 25 | R15: =$M15-$N15+$P15+$Q15 -> 434.5 | S15: 434.5 | T15: =ROUND($R15-$S15,2) -> 0 | U15: =IF(ABS($T15)<0.02,"OK","CHECK") -> OK | V15: roster PAID: part paid
A16: CH-013 | B16: FAM-010 | C16: BERGQVIST | D16: Rune | E16: Saturday | F16: Enrolled | G16: JAN-2026 | H16: 2026-009 | I16: =IF($J16<>"",$J16,IF($E16="Wednesday",INDEX(Terms!$D$4:$D$5,MATCH($G16,Terms!$A$4:$A$5,0)),INDEX(Terms!$C$4:$C$5,MATCH($G16,Terms!$A$4:$A$5,0)))) -> 21 | K16: =COUNTIFS($B$4:$B$500,$B16,$F$4:$F$500,"Enrolled") -> 2 | L16: =IF($F16<>"Enrolled",0,IF($K16=0,0,IF($E16="Wednesday",Rates!$C$9,INDEX(Rates!$C$4:$C$7,MIN($K16,4))/$K16))) -> 17.25 | M16: =ROUND($L16*$I16,2) -> 362.25 | N16: 0 | O16: supplies | P16: =IF(ISNUMBER(SEARCH("reg",$O16)),Rates!$C$11,0) -> 0 | Q16: =IF(ISNUMBER(SEARCH("supplies",$O16)),Rates!$C$12,0) -> 25 | R16: =$M16-$N16+$P16+$Q16 -> 387.25 | S16: 387.25 | T16: =ROUND($R16-$S16,2) -> 0 | U16: =IF(ABS($T16)<0.02,"OK","CHECK") -> OK | V16: roster PAID: paid
A17: CH-014 | B17: FAM-010 | C17: BERGQVIST | D17: Tamsin | E17: Saturday | F17: Enrolled | G17: JAN-2026 | H17: 2026-009a | I17: =IF($J17<>"",$J17,IF($E17="Wednesday",INDEX(Terms!$D$4:$D$5,MATCH($G17,Terms!$A$4:$A$5,0)),INDEX(Terms!$C$4:$C$5,MATCH($G17,Terms!$A$4:$A$5,0)))) -> 21 | K17: =COUNTIFS($B$4:$B$500,$B17,$F$4:$F$500,"Enrolled") -> 2 | L17: =IF($F17<>"Enrolled",0,IF($K17=0,0,IF($E17="Wednesday",Rates!$C$9,INDEX(Rates!$C$4:$C$7,MIN($K17,4))/$K17))) -> 17.25 | M17: =ROUND($L17*$I17,2) -> 362.25 | N17: 30 | P17: =IF(ISNUMBER(SEARCH("reg",$O17)),Rates!$C$11,0) -> 0 | Q17: =IF(ISNUMBER(SEARCH("supplies",$O17)),Rates!$C$12,0) -> 0 | R17: =$M17-$N17+$P17+$Q17 -> 332.25 | S17: 332.25 | T17: =ROUND($R17-$S17,2) -> 0 | U17: =IF(ABS($T17)<0.02,"OK","CHECK") -> OK | V17: roster PAID: paid
A18: CH-015 | B18: FAM-011 | C18: BLOMFIELD | D18: Solveig | E18: Saturday | F18: Enrolled | G18: JAN-2026 | H18: 2026-010 | I18: =IF($J18<>"",$J18,IF($E18="Wednesday",INDEX(Terms!$D$4:$D$5,MATCH($G18,Terms!$A$4:$A$5,0)),INDEX(Terms!$C$4:$C$5,MATCH($G18,Terms!$A$4:$A$5,0)))) -> 21 | K18: =COUNTIFS($B$4:$B$500,$B18,$F$4:$F$500,"Enrolled") -> 1 | L18: =IF($F18<>"Enrolled",0,IF($K18=0,0,IF($E18="Wednesday",Rates!$C$9,INDEX(Rates!$C$4:$C$7,MIN($K18,4))/$K18))) -> 19.5 | M18: =ROUND($L18*$I18,2) -> 409.5 | N18: 0 | O18: supplies | P18: =IF(ISNUMBER(SEARCH("reg",$O18)),Rates!$C$11,0) -> 0 | Q18: =IF(ISNUMBER(SEARCH("supplies",$O18)),Rates!$C$12,0) -> 25 | R18: =$M18-$N18+$P18+$Q18 -> 434.5 | S18: 434.5 | T18: =ROUND($R18-$S18,2) -> 0 | U18: =IF(ABS($T18)<0.02,"OK","CHECK") -> OK
A19: CH-016 | B19: FAM-012 | C19: BOSANQUET | D19: Hektor | E19: Saturday | F19: Enrolled | G19: JAN-2026 | H19: 2026-053a | I19: =IF($J19<>"",$J19,IF($E19="Wednesday",INDEX(Terms!$D$4:$D$5,MATCH($G19,Terms!$A$4:$A$5,0)),INDEX(Terms!$C$4:$C$5,MATCH($G19,Terms!$A$4:$A$5,0)))) -> 21 | K19: =COUNTIFS($B$4:$B$500,$B19,$F$4:$F$500,"Enrolled") -> 2 | L19: =IF($F19<>"Enrolled",0,IF($K19=0,0,IF($E19="Wednesday",Rates!$C$9,INDEX(Rates!$C$4:$C$7,MIN($K19,4))/$K19))) -> 17.25 | M19: =ROUND($L19*$I19,2) -> 362.25 | N19: 0 | O19: supplies | P19: =IF(ISNUMBER(SEARCH("reg",$O19)),Rates!$C$11,0) -> 0 | Q19: =IF(ISNUMBER(SEARCH("supplies",$O19)),Rates!$C$12,0) -> 25 | R19: =$M19-$N19+$P19+$Q19 -> 387.25 | S19: 387.25 | T19: =ROUND($R19-$S19,2) -> 0 | U19: =IF(ABS($T19)<0.02,"OK","CHECK") -> OK
A20: CH-017 | B20: FAM-012 | C20: BOSANQUET | D20: Rune | E20: Saturday | F20: Enrolled | G20: JAN-2026 | H20: 2026-053 | I20: =IF($J20<>"",$J20,IF($E20="Wednesday",INDEX(Terms!$D$4:$D$5,MATCH($G20,Terms!$A$4:$A$5,0)),INDEX(Terms!$C$4:$C$5,MATCH($G20,Terms!$A$4:$A$5,0)))) -> 21 | K20: =COUNTIFS($B$4:$B$500,$B20,$F$4:$F$500,"Enrolled") -> 2 | L20: =IF($F20<>"Enrolled",0,IF($K20=0,0,IF($E20="Wednesday",Rates!$C$9,INDEX(Rates!$C$4:$C$7,MIN($K20,4))/$K20))) -> 17.25 | M20: =ROUND($L20*$I20,2) -> 362.25 | N20: 0 | P20: =IF(ISNUMBER(SEARCH("reg",$O20)),Rates!$C$11,0) -> 0 | Q20: =IF(ISNUMBER(SEARCH("supplies",$O20)),Rates!$C$12,0) -> 0 | R20: =$M20-$N20+$P20+$Q20 -> 362.25 | S20: 362.25 | T20: =ROUND($R20-$S20,2) -> 0 | U20: =IF(ABS($T20)<0.02,"OK","CHECK") -> OK | V20: roster PAID: part paid
A21: CH-018 | B21: FAM-013 | C21: BRANNIGAN | D21: Dario | E21: Saturday | F21: Enrolled | G21: JAN-2026 | H21: 2026-055 | I21: =IF($J21<>"",$J21,IF($E21="Wednesday",INDEX(Terms!$D$4:$D$5,MATCH($G21,Terms!$A$4:$A$5,0)),INDEX(Terms!$C$4:$C$5,MATCH($G21,Terms!$A$4:$A$5,0)))) -> 21 | K21: =COUNTIFS($B$4:$B$500,$B21,$F$4:$F$500,"Enrolled") -> 4 | L21: =IF($F21<>"Enrolled",0,IF($K21=0,0,IF($E21="Wednesday",Rates!$C$9,INDEX(Rates!$C$4:$C$7,MIN($K21,4))/$K21))) -> 14.275 | M21: =ROUND($L21*$I21,2) -> 299.78 | N21: 0 | P21: =IF(ISNUMBER(SEARCH("reg",$O21)),Rates!$C$11,0) -> 0 | Q21: =IF(ISNUMBER(SEARCH("supplies",$O21)),Rates!$C$12,0) -> 0 | R21: =$M21-$N21+$P21+$Q21 -> 299.78 | S21: 299.78 | T21: =ROUND($R21-$S21,2) -> 0 | U21: =IF(ABS($T21)<0.02,"OK","CHECK") -> OK | V21: roster PAID: paid
A22: CH-019 | B22: FAM-013 | C22: BRANNIGAN | D22: Giulia | E22: Saturday | F22: Enrolled | G22: JAN-2026 | H22: 2026-055 | I22: =IF($J22<>"",$J22,IF($E22="Wednesday",INDEX(Terms!$D$4:$D$5,MATCH($G22,Terms!$A$4:$A$5,0)),INDEX(Terms!$C$4:$C$5,MATCH($G22,Terms!$A$4:$A$5,0)))) -> 21 | K22: =COUNTIFS($B$4:$B$500,$B22,$F$4:$F$500,"Enrolled") -> 4 | L22: =IF($F22<>"Enrolled",0,IF($K22=0,0,IF($E22="Wednesday",Rates!$C$9,INDEX(Rates!$C$4:$C$7,MIN($K22,4))/$K22))) -> 14.275 | M22: =ROUND($L22*$I22,2) -> 299.78 | N22: 0 | P22: =IF(ISNUMBER(SEARCH("reg",$O22)),Rates!$C$11,0) -> 0 | Q22: =IF(ISNUMBER(SEARCH("supplies",$O22)),Rates!$C$12,0) -> 0 | R22: =$M22-$N22+$P22+$Q22 -> 299.78 | S22: 299.78 | T22: =ROUND($R22-$S22,2) -> 0 | U22: =IF(ABS($T22)<0.02,"OK","CHECK") -> OK | V22: roster PAID: paid
A23: CH-020 | B23: FAM-013 | C23: BRANNIGAN | D23: Juniper | E23: Saturday | F23: Enrolled | G23: JAN-2026 | H23: 2026-055a | I23: =IF($J23<>"",$J23,IF($E23="Wednesday",INDEX(Terms!$D$4:$D$5,MATCH($G23,Terms!$A$4:$A$5,0)),INDEX(Terms!$C$4:$C$5,MATCH($G23,Terms!$A$4:$A$5,0)))) -> 21 | K23: =COUNTIFS($B$4:$B$500,$B23,$F$4:$F$500,"Enrolled") -> 4 | L23: =IF($F23<>"Enrolled",0,IF($K23=0,0,IF($E23="Wednesday",Rates!$C$9,INDEX(Rates!$C$4:$C$7,MIN($K23,4))/$K23))) -> 14.275 | M23: =ROUND($L23*$I23,2) -> 299.78 | N23: 0 | O23: reg, supplies | P23: =IF(ISNUMBER(SEARCH("reg",$O23)),Rates!$C$11,0) -> 25 | Q23: =IF(ISNUMBER(SEARCH("supplies",$O23)),Rates!$C$12,0) -> 25 | R23: =$M23-$N23+$P23+$Q23 -> 349.78 | S23: 349.78 | T23: =ROUND($R23-$S23,2) -> 0 | U23: =IF(ABS($T23)<0.02,"OK","CHECK") -> OK
A24: CH-021 | B24: FAM-013 | C24: BRANNIGAN | D24: Ndidi | E24: Saturday | F24: Enrolled | G24: JAN-2026 | H24: 2026-055 | I24: =IF($J24<>"",$J24,IF($E24="Wednesday",INDEX(Terms!$D$4:$D$5,MATCH($G24,Terms!$A$4:$A$5,0)),INDEX(Terms!$C$4:$C$5,MATCH($G24,Terms!$A$4:$A$5,0)))) -> 21 | K24: =COUNTIFS($B$4:$B$500,$B24,$F$4:$F$500,"Enrolled") -> 4 | L24: =IF($F24<>"Enrolled",0,IF($K24=0,0,IF($E24="Wednesday",Rates!$C$9,INDEX(Rates!$C$4:$C$7,MIN($K24,4))/$K24))) -> 14.275 | M24: =ROUND($L24*$I24,2) -> 299.78 | N24: 0 | P24: =IF(ISNUMBER(SEARCH("reg",$O24)),Rates!$C$11,0) -> 0 | Q24: =IF(ISNUMBER(SEARCH("supplies",$O24)),Rates!$C$12,0) -> 0 | R24: =$M24-$N24+$P24+$Q24 -> 299.78 | S24: 299.78 | T24: =ROUND($R24-$S24,2) -> 0 | U24: =IF(ABS($T24)<0.02,"OK","CHECK") -> OK | V24: roster PAID: paid
A25: CH-022 | B25: FAM-014 | C25: CARDOSO | D25: Caspian | E25: Saturday | F25: Enrolled | G25: JAN-2026 | H25: 2026-011 | I25: =IF($J25<>"",$J25,IF($E25="Wednesday",INDEX(Terms!$D$4:$D$5,MATCH($G25,Terms!$A$4:$A$5,0)),INDEX(Terms!$C$4:$C$5,MATCH($G25,Terms!$A$4:$A$5,0)))) -> 21 | K25: =COUNTIFS($B$4:$B$500,$B25,$F$4:$F$500,"Enrolled") -> 3 | L25: =IF($F25<>"Enrolled",0,IF($K25=0,0,IF($E25="Wednesday",Rates!$C$9,INDEX(Rates!$C$4:$C$7,MIN($K25,4))/$K25))) -> 15.333333 | M25: =ROUND($L25*$I25,2) -> 322 | N25: 0 | O25: supplies | P25: =IF(ISNUMBER(SEARCH("reg",$O25)),Rates!$C$11,0) -> 0 | Q25: =IF(ISNUMBER(SEARCH("supplies",$O25)),Rates!$C$12,0) -> 25 | R25: =$M25-$N25+$P25+$Q25 -> 347 | S25: 347 | T25: =ROUND($R25-$S25,2) -> 0 | U25: =IF(ABS($T25)<0.02,"OK","CHECK") -> OK | V25: roster PAID: paid
A26: CH-023 | B26: FAM-014 | C26: CARDOSO | D26: Dario | E26: Saturday | F26: Enrolled | G26: JAN-2026 | H26: 2026-011a | I26: =IF($J26<>"",$J26,IF($E26="Wednesday",INDEX(Terms!$D$4:$D$5,MATCH($G26,Terms!$A$4:$A$5,0)),INDEX(Terms!$C$4:$C$5,MATCH($G26,Terms!$A$4:$A$5,0)))) -> 21 | K26: =COUNTIFS($B$4:$B$500,$B26,$F$4:$F$500,"Enrolled") -> 3 | L26: =IF($F26<>"Enrolled",0,IF($K26=0,0,IF($E26="Wednesday",Rates!$C$9,INDEX(Rates!$C$4:$C$7,MIN($K26,4))/$K26))) -> 15.333333 | M26: =ROUND($L26*$I26,2) -> 322 | N26: 0 | O26: supplies | P26: =IF(ISNUMBER(SEARCH("reg",$O26)),Rates!$C$11,0) -> 0 | Q26: =IF(ISNUMBER(SEARCH("supplies",$O26)),Rates!$C$12,0) -> 25 | R26: =$M26-$N26+$P26+$Q26 -> 347 | S26: 347 | T26: =ROUND($R26-$S26,2) -> 0 | U26: =IF(ABS($T26)<0.02,"OK","CHECK") -> OK | V26: roster PAID: paid
A27: CH-024 | B27: FAM-014 | C27: CARDOSO | D27: Eleni | E27: Saturday | F27: Enrolled | G27: JAN-2026 | H27: 2026-011 | I27: =IF($J27<>"",$J27,IF($E27="Wednesday",INDEX(Terms!$D$4:$D$5,MATCH($G27,Terms!$A$4:$A$5,0)),INDEX(Terms!$C$4:$C$5,MATCH($G27,Terms!$A$4:$A$5,0)))) -> 21 | K27: =COUNTIFS($B$4:$B$500,$B27,$F$4:$F$500,"Enrolled") -> 3 | L27: =IF($F27<>"Enrolled",0,IF($K27=0,0,IF($E27="Wednesday",Rates!$C$9,INDEX(Rates!$C$4:$C$7,MIN($K27,4))/$K27))) -> 15.333333 | M27: =ROUND($L27*$I27,2) -> 322 | N27: 0 | O27: supplies | P27: =IF(ISNUMBER(SEARCH("reg",$O27)),Rates!$C$11,0) -> 0 | Q27: =IF(ISNUMBER(SEARCH("supplies",$O27)),Rates!$C$12,0) -> 25 | R27: =$M27-$N27+$P27+$Q27 -> 347 | S27: 347 | T27: =ROUND($R27-$S27,2) -> 0 | U27: =IF(ABS($T27)<0.02,"OK","CHECK") -> OK
A28: CH-025 | B28: FAM-015 | C28: CASTELLANE | D28: Quentin | E28: Saturday | F28: Enrolled | G28: JAN-2026 | H28: 2026-056a | I28: =IF($J28<>"",$J28,IF($E28="Wednesday",INDEX(Terms!$D$4:$D$5,MATCH($G28,Terms!$A$4:$A$5,0)),INDEX(Terms!$C$4:$C$5,MATCH($G28,Terms!$A$4:$A$5,0)))) -> 21 | K28: =COUNTIFS($B$4:$B$500,$B28,$F$4:$F$500,"Enrolled") -> 2 | L28: =IF($F28<>"Enrolled",0,IF($K28=0,0,IF($E28="Wednesday",Rates!$C$9,INDEX(Rates!$C$4:$C$7,MIN($K28,4))/$K28))) -> 17.25 | M28: =ROUND($L28*$I28,2) -> 362.25 | N28: 0 | O28: supplies | P28: =IF(ISNUMBER(SEARCH("reg",$O28)),Rates!$C$11,0) -> 0 | Q28: =IF(ISNUMBER(SEARCH("supplies",$O28)),Rates!$C$12,0) -> 25 | R28: =$M28-$N28+$P28+$Q28 -> 387.25 | S28: 387.25 | T28: =ROUND($R28-$S28,2) -> 0 | U28: =IF(ABS($T28)<0.02,"OK","CHECK") -> OK | V28: roster PAID: paid
A29: CH-026 | B29: FAM-015 | C29: CASTELLANE | D29: Zephyr | E29: Saturday | F29: Enrolled | G29: JAN-2026 | H29: 2026-056 | I29: =IF($J29<>"",$J29,IF($E29="Wednesday",INDEX(Terms!$D$4:$D$5,MATCH($G29,Terms!$A$4:$A$5,0)),INDEX(Terms!$C$4:$C$5,MATCH($G29,Terms!$A$4:$A$5,0)))) -> 21 | K29: =COUNTIFS($B$4:$B$500,$B29,$F$4:$F$500,"Enrolled") -> 2 | L29: =IF($F29<>"Enrolled",0,IF($K29=0,0,IF($E29="Wednesday",Rates!$C$9,INDEX(Rates!$C$4:$C$7,MIN($K29,4))/$K29))) -> 17.25 | M29: =ROUND($L29*$I29,2) -> 362.25 | N29: 0 | O29: supplies | P29: =IF(ISNUMBER(SEARCH("reg",$O29)),Rates!$C$11,0) -> 0 | Q29: =IF(ISNUMBER(SEARCH("supplies",$O29)),Rates!$C$12,0) -> 25 | R29: =$M29-$N29+$P29+$Q29 -> 387.25 | S29: 387.25 | T29: =ROUND($R29-$S29,2) -> 0 | U29: =IF(ABS($T29)<0.02,"OK","CHECK") -> OK | V29: roster PAID: part paid
A30: CH-027 | B30: FAM-016 | C30: CHIDOZIE | D30: Amara | E30: Saturday | F30: Not invoiced | G30: JAN-2026 | I30: =IF($J30<>"",$J30,IF($E30="Wednesday",INDEX(Terms!$D$4:$D$5,MATCH($G30,Terms!$A$4:$A$5,0)),INDEX(Terms!$C$4:$C$5,MATCH($G30,Terms!$A$4:$A$5,0)))) -> 21 | K30: =COUNTIFS($B$4:$B$500,$B30,$F$4:$F$500,"Enrolled") -> 0 | L30: =IF($F30<>"Enrolled",0,IF($K30=0,0,IF($E30="Wednesday",Rates!$C$9,INDEX(Rates!$C$4:$C$7,MIN($K30,4))/$K30))) -> 0 | M30: =ROUND($L30*$I30,2) -> 0 | N30: 0 | O30: supplies | P30: =IF(ISNUMBER(SEARCH("reg",$O30)),Rates!$C$11,0) -> 0 | Q30: =IF(ISNUMBER(SEARCH("supplies",$O30)),Rates!$C$12,0) -> 25 | R30: =$M30-$N30+$P30+$Q30 -> 25 | S30: 25 | T30: =ROUND($R30-$S30,2) -> 0 | U30: =IF(ABS($T30)<0.02,"OK","CHECK") -> OK | V30: roster PAID: part paid
A31: CH-028 | B31: FAM-017 | C31: CHIDOZIE | D31: Delphine | E31: Saturday | F31: Enrolled | G31: JAN-2026 | H31: 2026-012 | I31: =IF($J31<>"",$J31,IF($E31="Wednesday",INDEX(Terms!$D$4:$D$5,MATCH($G31,Terms!$A$4:$A$5,0)),INDEX(Terms!$C$4:$C$5,MATCH($G31,Terms!$A$4:$A$5,0)))) -> 21 | K31: =COUNTIFS($B$4:$B$500,$B31,$F$4:$F$500,"Enrolled") -> 2 | L31: =IF($F31<>"Enrolled",0,IF($K31=0,0,IF($E31="Wednesday",Rates!$C$9,INDEX(Rates!$C$4:$C$7,MIN($K31,4))/$K31))) -> 17.25 | M31: =ROUND($L31*$I31,2) -> 362.25 | N31: 0 | O31: supplies | P31: =IF(ISNUMBER(SEARCH("reg",$O31)),Rates!$C$11,0) -> 0 | Q31: =IF(ISNUMBER(SEARCH("supplies",$O31)),Rates!$C$12,0) -> 25 | R31: =$M31-$N31+$P31+$Q31 -> 387.25 | S31: 347 | T31: =ROUND($R31-$S31,2) -> 40.25 | U31: =IF(ABS($T31)<0.02,"OK","CHECK") -> CHECK | V31: roster PAID: part paid
A32: CH-029 | B32: FAM-017 | C32: CHIDOZIE | D32: Zephyr | E32: Saturday | F32: Enrolled | G32: JAN-2026 | H32: 2026-012a | I32: =IF($J32<>"",$J32,IF($E32="Wednesday",INDEX(Terms!$D$4:$D$5,MATCH($G32,Terms!$A$4:$A$5,0)),INDEX(Terms!$C$4:$C$5,MATCH($G32,Terms!$A$4:$A$5,0)))) -> 21 | K32: =COUNTIFS($B$4:$B$500,$B32,$F$4:$F$500,"Enrolled") -> 2 | L32: =IF($F32<>"Enrolled",0,IF($K32=0,0,IF($E32="Wednesday",Rates!$C$9,INDEX(Rates!$C$4:$C$7,MIN($K32,4))/$K32))) -> 17.25 | M32: =ROUND($L32*$I32,2) -> 362.25 | N32: 0 | O32: supplies | P32: =IF(ISNUMBER(SEARCH("reg",$O32)),Rates!$C$11,0) -> 0 | Q32: =IF(ISNUMBER(SEARCH("supplies",$O32)),Rates!$C$12,0) -> 25 | R32: =$M32-$N32+$P32+$Q32 -> 387.25 | S32: 347 | T32: =ROUND($R32-$S32,2) -> 40.25 | U32: =IF(ABS($T32)<0.02,"OK","CHECK") -> CHECK | V32: roster PAID: paid
A33: CH-030 | B33: FAM-018 | C33: COMEAU | D33: Olamide | E33: Saturday | F33: Enrolled | G33: JAN-2026 | H33: 2026-013 | I33: =IF($J33<>"",$J33,IF($E33="Wednesday",INDEX(Terms!$D$4:$D$5,MATCH($G33,Terms!$A$4:$A$5,0)),INDEX(Terms!$C$4:$C$5,MATCH($G33,Terms!$A$4:$A$5,0)))) -> 21 | K33: =COUNTIFS($B$4:$B$500,$B33,$F$4:$F$500,"Enrolled") -> 1 | L33: =IF($F33<>"Enrolled",0,IF($K33=0,0,IF($E33="Wednesday",Rates!$C$9,INDEX(Rates!$C$4:$C$7,MIN($K33,4))/$K33))) -> 19.5 | M33: =ROUND($L33*$I33,2) -> 409.5 | N33: 0 | P33: =IF(ISNUMBER(SEARCH("reg",$O33)),Rates!$C$11,0) -> 0 | Q33: =IF(ISNUMBER(SEARCH("supplies",$O33)),Rates!$C$12,0) -> 0 | R33: =$M33-$N33+$P33+$Q33 -> 409.5 | S33: 409.5 | T33: =ROUND($R33-$S33,2) -> 0 | U33: =IF(ABS($T33)<0.02,"OK","CHECK") -> OK | V33: roster PAID: paid
A34: CH-031 | B34: FAM-019 | C34: DARRIEUSSECQ | D34: Valentin | E34: Saturday | F34: Enrolled | G34: JAN-2026 | H34: 2026-014 | I34: =IF($J34<>"",$J34,IF($E34="Wednesday",INDEX(Terms!$D$4:$D$5,MATCH($G34,Terms!$A$4:$A$5,0)),INDEX(Terms!$C$4:$C$5,MATCH($G34,Terms!$A$4:$A$5,0)))) -> 21 | K34: =COUNTIFS($B$4:$B$500,$B34,$F$4:$F$500,"Enrolled") -> 1 | L34: =IF($F34<>"Enrolled",0,IF($K34=0,0,IF($E34="Wednesday",Rates!$C$9,INDEX(Rates!$C$4:$C$7,MIN($K34,4))/$K34))) -> 19.5 | M34: =ROUND($L34*$I34,2) -> 409.5 | N34: 0 | O34: supplies | P34: =IF(ISNUMBER(SEARCH("reg",$O34)),Rates!$C$11,0) -> 0 | Q34: =IF(ISNUMBER(SEARCH("supplies",$O34)),Rates!$C$12,0) -> 25 | R34: =$M34-$N34+$P34+$Q34 -> 434.5 | S34: 434.5 | T34: =ROUND($R34-$S34,2) -> 0 | U34: =IF(ABS($T34)<0.02,"OK","CHECK") -> OK
A35: CH-032 | B35: FAM-020 | C35: DELACROIX | D35: Fabienne | E35: Saturday | F35: Enrolled | G35: JAN-2026 | H35: 2026-015 | I35: =IF($J35<>"",$J35,IF($E35="Wednesday",INDEX(Terms!$D$4:$D$5,MATCH($G35,Terms!$A$4:$A$5,0)),INDEX(Terms!$C$4:$C$5,MATCH($G35,Terms!$A$4:$A$5,0)))) -> 21 | K35: =COUNTIFS($B$4:$B$500,$B35,$F$4:$F$500,"Enrolled") -> 3 | L35: =IF($F35<>"Enrolled",0,IF($K35=0,0,IF($E35="Wednesday",Rates!$C$9,INDEX(Rates!$C$4:$C$7,MIN($K35,4))/$K35))) -> 15.333333 | M35: =ROUND($L35*$I35,2) -> 322 | N35: 0 | O35: supplies | P35: =IF(ISNUMBER(SEARCH("reg",$O35)),Rates!$C$11,0) -> 0 | Q35: =IF(ISNUMBER(SEARCH("supplies",$O35)),Rates!$C$12,0) -> 25 | R35: =$M35-$N35+$P35+$Q35 -> 347 | S35: 347 | T35: =ROUND($R35-$S35,2) -> 0 | U35: =IF(ABS($T35)<0.02,"OK","CHECK") -> OK | V35: roster PAID: part paid
A36: CH-033 | B36: FAM-020 | C36: DELACROIX | D36: Matteo | E36: Saturday | F36: Enrolled | G36: JAN-2026 | H36: 2026-015 | I36: =IF($J36<>"",$J36,IF($E36="Wednesday",INDEX(Terms!$D$4:$D$5,MATCH($G36,Terms!$A$4:$A$5,0)),INDEX(Terms!$C$4:$C$5,MATCH($G36,Terms!$A$4:$A$5,0)))) -> 21 | K36: =COUNTIFS($B$4:$B$500,$B36,$F$4:$F$500,"Enrolled") -> 3 | L36: =IF($F36<>"Enrolled",0,IF($K36=0,0,IF($E36="Wednesday",Rates!$C$9,INDEX(Rates!$C$4:$C$7,MIN($K36,4))/$K36))) -> 15.333333 | M36: =ROUND($L36*$I36,2) -> 322 | N36: 0 | O36: supplies | P36: =IF(ISNUMBER(SEARCH("reg",$O36)),Rates!$C$11,0) -> 0 | Q36: =IF(ISNUMBER(SEARCH("supplies",$O36)),Rates!$C$12,0) -> 25 | R36: =$M36-$N36+$P36+$Q36 -> 347 | S36: 347 | T36: =ROUND($R36-$S36,2) -> 0 | U36: =IF(ABS($T36)<0.02,"OK","CHECK") -> OK
A37: CH-034 | B37: FAM-020 | C37: DELACROIX | D37: Yusuf | E37: Saturday | F37: Enrolled | G37: JAN-2026 | H37: 2026-015a | I37: =IF($J37<>"",$J37,IF($E37="Wednesday",INDEX(Terms!$D$4:$D$5,MATCH($G37,Terms!$A$4:$A$5,0)),INDEX(Terms!$C$4:$C$5,MATCH($G37,Terms!$A$4:$A$5,0)))) -> 21 | K37: =COUNTIFS($B$4:$B$500,$B37,$F$4:$F$500,"Enrolled") -> 3 | L37: =IF($F37<>"Enrolled",0,IF($K37=0,0,IF($E37="Wednesday",Rates!$C$9,INDEX(Rates!$C$4:$C$7,MIN($K37,4))/$K37))) -> 15.333333 | M37: =ROUND($L37*$I37,2) -> 322 | N37: 0 | O37: supplies | P37: =IF(ISNUMBER(SEARCH("reg",$O37)),Rates!$C$11,0) -> 0 | Q37: =IF(ISNUMBER(SEARCH("supplies",$O37)),Rates!$C$12,0) -> 25 | R37: =$M37-$N37+$P37+$Q37 -> 347 | S37: 347 | T37: =ROUND($R37-$S37,2) -> 0 | U37: =IF(ABS($T37)<0.02,"OK","CHECK") -> OK | V37: roster PAID: paid
A38: CH-035 | B38: FAM-021 | C38: DUPLANTIER | D38: Halima | E38: Saturday | F38: Enrolled | G38: JAN-2026 | H38: 2026-016 | I38: =IF($J38<>"",$J38,IF($E38="Wednesday",INDEX(Terms!$D$4:$D$5,MATCH($G38,Terms!$A$4:$A$5,0)),INDEX(Terms!$C$4:$C$5,MATCH($G38,Terms!$A$4:$A$5,0)))) -> 21 | K38: =COUNTIFS($B$4:$B$500,$B38,$F$4:$F$500,"Enrolled") -> 1 | L38: =IF($F38<>"Enrolled",0,IF($K38=0,0,IF($E38="Wednesday",Rates!$C$9,INDEX(Rates!$C$4:$C$7,MIN($K38,4))/$K38))) -> 19.5 | M38: =ROUND($L38*$I38,2) -> 409.5 | N38: 0 | P38: =IF(ISNUMBER(SEARCH("reg",$O38)),Rates!$C$11,0) -> 0 | Q38: =IF(ISNUMBER(SEARCH("supplies",$O38)),Rates!$C$12,0) -> 0 | R38: =$M38-$N38+$P38+$Q38 -> 409.5 | S38: 409.5 | T38: =ROUND($R38-$S38,2) -> 0 | U38: =IF(ABS($T38)<0.02,"OK","CHECK") -> OK
A39: CH-036 | B39: FAM-022 | C39: DZIEDZIC | D39: Solveig | E39: Saturday | F39: Enrolled | G39: JAN-2026 | H39: 2026-057 | I39: =IF($J39<>"",$J39,IF($E39="Wednesday",INDEX(Terms!$D$4:$D$5,MATCH($G39,Terms!$A$4:$A$5,0)),INDEX(Terms!$C$4:$C$5,MATCH($G39,Terms!$A$4:$A$5,0)))) -> 21 | K39: =COUNTIFS($B$4:$B$500,$B39,$F$4:$F$500,"Enrolled") -> 1 | L39: =IF($F39<>"Enrolled",0,IF($K39=0,0,IF($E39="Wednesday",Rates!$C$9,INDEX(Rates!$C$4:$C$7,MIN($K39,4))/$K39))) -> 19.5 | M39: =ROUND($L39*$I39,2) -> 409.5 | N39: 0 | O39: supplies | P39: =IF(ISNUMBER(SEARCH("reg",$O39)),Rates!$C$11,0) -> 0 | Q39: =IF(ISNUMBER(SEARCH("supplies",$O39)),Rates!$C$12,0) -> 25 | R39: =$M39-$N39+$P39+$Q39 -> 434.5 | S39: 434.5 | T39: =ROUND($R39-$S39,2) -> 0 | U39: =IF(ABS($T39)<0.02,"OK","CHECK") -> OK | V39: roster PAID: paid
A40: CH-037 | B40: FAM-023 | C40: ERIKSEN | D40: Giulia | E40: Saturday | F40: Enrolled | G40: JAN-2026 | H40: 2026-017 | I40: =IF($J40<>"",$J40,IF($E40="Wednesday",INDEX(Terms!$D$4:$D$5,MATCH($G40,Terms!$A$4:$A$5,0)),INDEX(Terms!$C$4:$C$5,MATCH($G40,Terms!$A$4:$A$5,0)))) -> 21 | K40: =COUNTIFS($B$4:$B$500,$B40,$F$4:$F$500,"Enrolled") -> 1 | L40: =IF($F40<>"Enrolled",0,IF($K40=0,0,IF($E40="Wednesday",Rates!$C$9,INDEX(Rates!$C$4:$C$7,MIN($K40,4))/$K40))) -> 19.5 | M40: =ROUND($L40*$I40,2) -> 409.5 | N40: 0 | O40: supplies | P40: =IF(ISNUMBER(SEARCH("reg",$O40)),Rates!$C$11,0) -> 0 | Q40: =IF(ISNUMBER(SEARCH("supplies",$O40)),Rates!$C$12,0) -> 25 | R40: =$M40-$N40+$P40+$Q40 -> 434.5 | S40: 434.5 | T40: =ROUND($R40-$S40,2) -> 0 | U40: =IF(ABS($T40)<0.02,"OK","CHECK") -> OK | V40: roster PAID: paid
A41: CH-038 | B41: FAM-024 | C41: FALZON | D41: Jomo | E41: Saturday | F41: Enrolled | G41: JAN-2026 | H41: 2026-018 | I41: =IF($J41<>"",$J41,IF($E41="Wednesday",INDEX(Terms!$D$4:$D$5,MATCH($G41,Terms!$A$4:$A$5,0)),INDEX(Terms!$C$4:$C$5,MATCH($G41,Terms!$A$4:$A$5,0)))) -> 21 | K41: =COUNTIFS($B$4:$B$500,$B41,$F$4:$F$500,"Enrolled") -> 1 | L41: =IF($F41<>"Enrolled",0,IF($K41=0,0,IF($E41="Wednesday",Rates!$C$9,INDEX(Rates!$C$4:$C$7,MIN($K41,4))/$K41))) -> 19.5 | M41: =ROUND($L41*$I41,2) -> 409.5 | N41: 0 | O41: reg | P41: =IF(ISNUMBER(SEARCH("reg",$O41)),Rates!$C$11,0) -> 25 | Q41: =IF(ISNUMBER(SEARCH("supplies",$O41)),Rates!$C$12,0) -> 0 | R41: =$M41-$N41+$P41+$Q41 -> 434.5 | S41: 434.5 | T41: =ROUND($R41-$S41,2) -> 0 | U41: =IF(ABS($T41)<0.02,"OK","CHECK") -> OK | V41: roster PAID: paid
...

Sheet Receipts
A1: Receipts — one row per bank line. Blue = from the bank file. Yellow = your decision. Everything else is written by the engine.
A3: Date | B3: Amount | C3: Payer (bank) | D3: Reference (bank) | E3: Term | F3: Family override (fill in) | G3: Family | H3: Allocated | I3: Tier | J3: Candidates | K3: Why | L3: Amount check | M3: Flags | N3: Full memo
A4: 46029 | B4: 434.5 | C4: ZORA VANTERPOOL | D4: Halima | E4: JAN-2026 | G4: =IF($F4<>"",$F4,$J4) -> FAM-055 | H4: =IF($G4<>"","yes","") -> yes | I4: B | J4: FAM-055 | L4: surname VANTERPOOL | M4: matches expected; JAN-2026 amount | N4: ZORA VANTERPOOL Halima BGC
A5: 46034 | B5: 434.5 | C5: VERA FALZON | D5: 2026018 | E5: JAN-2026 | G5: =IF($F5<>"",$F5,$J5) -> FAM-024 | H5: =IF($G5<>"","yes","") -> yes | I5: A | J5: FAM-024 | L5: invoice reference 2026-018 | M5: matches expected; JAN-2026 amount | N5: VERA FALZON 2026018 BGC
A6: 46038 | B6: 229.75 | C6: MARGIT RASMUSSEN | D6: 2026-039 | E6: JAN-2026 | G6: =IF($F6<>"",$F6,$J6) -> 0 | H6: =IF($G6<>"","yes","") | I6: X | K6: FAM-048, FAM-049 | L6: reference 2026-039 points to FAM-049 but the memo names FAM-048 — parent may have typed the wrong invoice number | N6: MARGIT RASMUSSEN 2026-039 BGC
A7: 46041 | B7: 217.25 | C7: INGRID ERIKSEN | D7: ERIKSE2026-017 | E7: JAN-2026 | G7: =IF($F7<>"",$F7,$J7) -> FAM-023 | H7: =IF($G7<>"","yes","") -> yes | I7: A | J7: FAM-023 | L7: invoice reference 2026-017 | M7: half of expected | N7: INGRID ERIKSEN ERIKSE2026-017 BGC
A8: 46042 | B8: 1184 | C8: GENEVIEVE BELHADJ | D8: 2026-008 | E8: JAN-2026 | G8: =IF($F8<>"",$F8,$J8) -> FAM-008 | H8: =IF($G8<>"","yes","") -> yes | I8: A | J8: FAM-008 | L8: invoice reference 2026-008 | M8: unusual (expected £774.50) | N8: GENEVIEVE BELHADJ 2026-008 BGC
A9: 46044 | B9: 217.25 | C9: MARGIT GAILLARD | D9: Esben | E9: JAN-2026 | G9: =IF($F9<>"",$F9,$J9) -> FAM-027 | H9: =IF($G9<>"","yes","") -> yes | I9: B | J9: FAM-027 | L9: child first name Esben, surname GAILLARD | M9: half of expected | N9: MARGIT GAILLARD Esben BGC
A10: 46044 | B10: 434.5 | C10: LUDOVIC ASHWORTH | D10: ASHWORTH FRENCH SCHOO | E10: JAN-2026 | G10: =IF($F10<>"",$F10,$J10) -> FAM-004 | H10: =IF($G10<>"","yes","") -> yes | I10: B | J10: FAM-004 | L10: surname ASHWORTH | M10: matches expected; JAN-2026 amount | N10: LUDOVIC ASHWORTH ASHWORTH FRENCH SCHOO BGC
A11: 46048 | B11: 204.75 | C11: KATRIN DUPLANTIER | D11: 2025-608 | E11: AUT-2025 | G11: =IF($F11<>"",$F11,$J11) -> FAM-021 | H11: =IF($G11<>"","yes","") -> yes | I11: B | J11: FAM-021 | L11: surname DUPLANTIER (prior-term reference 2025-608 — family identified, invoice not loaded) | M11: JAN-2026 amount | N11: KATRIN DUPLANTIER 2025-608 BGC
A12: 46048 | B12: 387.25 | C12: GENEVIEVE MAALOUF | D12: MAALOU2026-030 | E12: JAN-2026 | G12: =IF($F12<>"",$F12,$J12) -> FAM-039 | H12: =IF($G12<>"","yes","") -> yes | I12: A | J12: FAM-039 | L12: invoice reference 2026-030 | M12: half of expected | N12: GENEVIEVE MAALOUF MAALOU2026-030 BGC
A13: 46053 | B13: 434.5 | C13: ELODIE HASANOVIC | D13: 060 | E13: JAN-2026 | G13: =IF($F13<>"",$F13,$J13) -> FAM-031 | H13: =IF($G13<>"","yes","") -> yes | I13: B | J13: FAM-031 | L13: surname HASANOVIC | M13: matches expected; JAN-2026 amount | N13: ELODIE HASANOVIC 060 BGC
A14: 46053 | B14: 374.75 | C14: CAMILLE SIGURDSSON | D14: 2026041 | E14: JAN-2026 | G14: =IF($F14<>"",$F14,$J14) -> FAM-051 | H14: =IF($G14<>"","yes","") -> yes | I14: A | J14: FAM-051 | L14: invoice reference 2026-041 | M14: half of expected | N14: CAMILLE SIGURDSSON 2026041 BGC
A15: 46053 | B15: 1041 | C15: BETTINA DELACROIX | D15: 2026-015 | E15: JAN-2026 | G15: =IF($F15<>"",$F15,$J15) -> FAM-020 | H15: =IF($G15<>"","yes","") -> yes | I15: A | J15: FAM-020 | L15: invoice reference 2026-015 | M15: matches expected; JAN-2026 amount | N15: BETTINA DELACROIX 2026-015 BGC
A16: 46054 | B16: 434.5 | C16: NILS OKONKWO | D16: 2025-508 | E16: AUT-2025 | G16: =IF($F16<>"",$F16,$J16) -> FAM-044 | H16: =IF($G16<>"","yes","") -> yes | I16: B | J16: FAM-044 | L16: surname OKONKWO (prior-term reference 2025-508 — family identified, invoice not loaded) | M16: JAN-2026 amount | N16: NILS OKONKWO 2025-508 BGC
A17: 46057 | B17: 434.5 | C17: NILS DZIEDZIC | D17: 2026057 | E17: JAN-2026 | G17: =IF($F17<>"",$F17,$J17) -> FAM-022 | H17: =IF($G17<>"","yes","") -> yes | I17: A | J17: FAM-022 | L17: invoice reference 2026-057 | M17: matches expected; JAN-2026 amount | N17: NILS DZIEDZIC 2026057 BGC
A18: 46058 | B18: 520.5 | C18: GENEVIEVE KILBRIDE | D18: 2025-611 | E18: AUT-2025 | G18: =IF($F18<>"",$F18,$J18) -> FAM-036 | H18: =IF($G18<>"","yes","") -> yes | I18: A | J18: FAM-036 | L18: payer name previously seen with a verified reference for this family (prior-term reference 2025-611 — family identified, invoice not loaded) | N18: GENEVIEVE KILBRIDE 2025-611 BGC
A19: 46059 | B19: 229.75 | C19: MARGIT RASMUSSEN | D19: Rasmussen | E19: JAN-2026 | G19: =IF($F19<>"",$F19,$J19) -> FAM-048 | H19: =IF($G19<>"","yes","") -> yes | I19: B | J19: FAM-048 | L19: surname RASMUSSEN | M19: half of expected | N19: MARGIT RASMUSSEN Rasmussen BGC
A20: 46060 | B20: 409.5 | C20: BETTINA VILLALOBOS | D20: 2025-578 | E20: AUT-2025 | G20: =IF($F20<>"",$F20,$J20) -> FAM-056 | H20: =IF($G20<>"","yes","") -> yes | I20: B | J20: FAM-056 | L20: surname VILLALOBOS (prior-term reference 2025-578 — family identified, invoice not loaded) | M20: JAN-2026 amount | N20: BETTINA VILLALOBOS 2025-578 BGC
A21: 46060 | B21: 217.25 | C21: INGRID ERIKSEN | D21: Eriksen 2nd | E21: JAN-2026 | G21: =IF($F21<>"",$F21,$J21) -> FAM-023 | H21: =IF($G21<>"","yes","") -> yes | I21: A | J21: FAM-023 | L21: payer name previously seen with a verified reference for this family | M21: half of expected | N21: INGRID ERIKSEN Eriksen 2nd BGC
A22: 46063 | B22: 434.5 | C22: KATRIN NAKASHIMA | D22: 2026-032 | E22: JAN-2026 | G22: =IF($F22<>"",$F22,$J22) -> FAM-041 | H22: =IF($G22<>"","yes","") -> yes | I22: A | J22: FAM-041 | L22: invoice reference 2026-032 | M22: matches expected; JAN-2026 amount | N22: KATRIN NAKASHIMA 2026-032 BGC
A23: 46063 | B23: 387.25 | C23: GENEVIEVE MAALOUF | D23: 2nd payment | E23: JAN-2026 | G23: =IF($F23<>"",$F23,$J23) -> FAM-039 | H23: =IF($G23<>"","yes","") -> yes | I23: A | J23: FAM-039 | L23: payer name previously seen with a verified reference for this family | M23: half of expected | N23: GENEVIEVE MAALOUF 2nd payment BGC
A24: 46064 | B24: 204.75 | C24: KATRIN DUPLANTIER | D24: 2nd payment | E24: JAN-2026 | G24: =IF($F24<>"",$F24,$J24) -> FAM-021 | H24: =IF($G24<>"","yes","") -> yes | I24: B | J24: FAM-021 | L24: surname DUPLANTIER | M24: half of expected; JAN-2026 amount | N24: KATRIN DUPLANTIER 2nd payment BGC
A25: 46064 | B25: 409.5 | C25: TOVE YANKOVIC | D25: Yankovic | E25: JAN-2026 | G25: =IF($F25<>"",$F25,$J25) -> FAM-059 | H25: =IF($G25<>"","yes","") -> yes | I25: B | J25: FAM-059 | L25: surname YANKOVIC | M25: matches expected; JAN-2026 amount | N25: TOVE YANKOVIC Yankovic BGC
A26: 46065 | B26: 719.5 | C26: STEFAN BERGQVIST | D26: BERGQV2026-009 | E26: JAN-2026 | G26: =IF($F26<>"",$F26,$J26) -> FAM-010 | H26: =IF($G26<>"","yes","") -> yes | I26: A | J26: FAM-010 | L26: invoice reference 2026-009 | M26: matches expected | N26: STEFAN BERGQVIST BERGQV2026-009 BGC
A27: 46068 | B27: 767.5 | C27: ROSALIND NAKASHIMA-PELL | D27: 2025-641 | E27: AUT-2025 | G27: =IF($F27<>"",$F27,$J27) -> FAM-042 | H27: =IF($G27<>"","yes","") -> yes | I27: B | J27: FAM-042 | L27: 'PELL' starts PELLETIER, surname NAKASHIMA (prior-term reference 2025-641 — family identified, invoice not loaded) | N27: ROSALIND NAKASHIMA-PELL 2025-641 BGC
A28: 46069 | B28: 409.5 | C28: MARGIT NWACHUKWU | D28: Giulia | E28: JAN-2026 | G28: =IF($F28<>"",$F28,$J28) -> FAM-043 | H28: =IF($G28<>"","yes","") -> yes | I28: B | J28: FAM-043 | L28: surname NWACHUKWU | M28: matches expected; JAN-2026 amount | N28: MARGIT NWACHUKWU Giulia BGC
A29: 46070 | B29: 434.5 | C29: KATRIN BEAUCHAMP | D29: 2026-008 | E29: JAN-2026 | G29: =IF($F29<>"",$F29,$J29) -> 0 | H29: =IF($G29<>"","yes","") | I29: D | K29: FAM-008, FAM-045 | L29: reference 2026-008 is shared by FAM-008, FAM-045 | M29: JAN-2026 amount | N29: KATRIN BEAUCHAMP 2026-008 BGC
A30: 46070 | B30: 774.5 | C30: ULRICH QUILLIAM | D30: school fees | E30: JAN-2026 | G30: =IF($F30<>"",$F30,$J30) -> FAM-047 | H30: =IF($G30<>"","yes","") -> yes | I30: B | J30: FAM-047 | L30: surname QUILLIAM | M30: matches expected; JAN-2026 amount | N30: ULRICH QUILLIAM school fees BGC
A31: 46070 | B31: 204.75 | C31: LUDOVIC THIBODEAUX | D31: Thibodeaux fees | E31: JAN-2026 | G31: =IF($F31<>"",$F31,$J31) -> FAM-052 | H31: =IF($G31<>"","yes","") -> yes | I31: B | J31: FAM-052 | L31: surname THIBODEAUX | M31: half of expected; JAN-2026 amount | N31: LUDOVIC THIBODEAUX Thibodeaux fees BGC
A32: 46071 | B32: 799.5 | C32: ULRICH TREVELYAN | D32: Trevelyan | E32: JAN-2026 | G32: =IF($F32<>"",$F32,$J32) -> 0 | H32: =IF($G32<>"","yes","") | I32: D | K32: FAM-009, FAM-053 | L32: several families fit: FAM-009 (surname TREVELYAN); FAM-053 (surname TREVELYAN) | M32: JAN-2026 amount | N32: ULRICH TREVELYAN Trevelyan BGC
A33: 46073 | B33: 1299.12 | C33: PASCAL HALVORSEN | D33: HALVOR2026-022 | E33: JAN-2026 | G33: =IF($F33<>"",$F33,$J33) -> FAM-030 | H33: =IF($G33<>"","yes","") -> yes | I33: A | J33: FAM-030 | L33: invoice reference 2026-022 | M33: matches expected | N33: PASCAL HALVORSEN HALVOR2026-022 BGC
A34: 46075 | B34: 1041 | C34: PASCAL GRIMALDSEN | D34: Grimaldsen fees | E34: JAN-2026 | G34: =IF($F34<>"",$F34,$J34) -> FAM-028 | H34: =IF($G34<>"","yes","") -> yes | I34: B | J34: FAM-028 | L34: surname GRIMALDSEN | M34: matches expected; JAN-2026 amount | N34: PASCAL GRIMALDSEN Grimaldsen fees BGC
A35: 46075 | B35: 217.25 | C35: TOVE FITZHUGH | D35: 2026-019 | E35: JAN-2026 | G35: =IF($F35<>"",$F35,$J35) -> FAM-026 | H35: =IF($G35<>"","yes","") -> yes | I35: A | J35: FAM-026 | L35: invoice reference 2026-019 | M35: half of expected | N35: TOVE FITZHUGH 2026-019 BGC
A36: 46077 | B36: 434.5 | C36: GENEVIEVE HOLLINGWORTH | D36: 2026-024 | E36: JAN-2026 | G36: =IF($F36<>"",$F36,$J36) -> 0 | H36: =IF($G36<>"","yes","") | I36: X | K36: FAM-032, FAM-033 | L36: reference 2026-024 points to FAM-033 but the memo names FAM-032 — parent may have typed the wrong invoice number | M36: JAN-2026 amount | N36: GENEVIEVE HOLLINGWORTH 2026-024 BGC
A37: 46077 | B37: 434.5 | C37: HUGO WOJCIECHOWSKI | D37: 048 | E37: JAN-2026 | G37: =IF($F37<>"",$F37,$J37) -> FAM-058 | H37: =IF($G37<>"","yes","") -> yes | I37: B | J37: FAM-058 | L37: surname WOJCIECHOWSKI | M37: matches expected; JAN-2026 amount | N37: HUGO WOJCIECHOWSKI 048 BGC
A38: 46078 | B38: 520.5 | C38: GENEVIEVE KILBRIDE | D38: 2026-027 | E38: JAN-2026 | G38: =IF($F38<>"",$F38,$J38) -> FAM-036 | H38: =IF($G38<>"","yes","") -> yes | I38: A | J38: FAM-036 | L38: invoice reference 2026-027 | M38: half of expected | N38: GENEVIEVE KILBRIDE 2026-027 BGC
A39: 46080 | B39: 204.75 | C39: ZORA ZIMMERLI | D39: 2025-574 | E39: AUT-2025 | G39: =IF($F39<>"",$F39,$J39) -> FAM-061 | H39: =IF($G39<>"","yes","") -> yes | I39: B | J39: FAM-061 | L39: surname ZIMMERLI (prior-term reference 2025-574 — family identified, invoice not loaded) | M39: JAN-2026 amount | N39: ZORA ZIMMERLI 2025-574 BGC
A40: 46083 | B40: 374.75 | C40: CAMILLE SIGURDSSON | D40: 2nd payment | E40: JAN-2026 | G40: =IF($F40<>"",$F40,$J40) -> FAM-051 | H40: =IF($G40<>"","yes","") -> yes | I40: A | J40: FAM-051 | L40: payer name previously seen with a verified reference for this family | M40: half of expected | N40: CAMILLE SIGURDSSON 2nd payment BGC
A41: 46085 | B41: 217.25 | C41: MARGIT GAILLARD | D41: Gaillard | E41: JAN-2026 | G41: =IF($F41<>"",$F41,$J41) -> FAM-027 | H41: =IF($G41<>"","yes","") -> yes | I41: B | J41: FAM-027 | L41: surname GAILLARD | M41: half of expected | N41: MARGIT GAILLARD Gaillard BGC
...

Sheet Review
A1: Review queue — receipts the engine would not allocate. Decide, then type the family ID into Receipts column M (row shown) and re-run.
A3: Row in Receipts | B3: Date | C3: Amount | D3: Payer (bank) | E3: Reference (bank) | F3: Term | G3: Tier | H3: Most likely family | I3: Why the engine stopped | J3: Amount check | K3: That family's expected fee
A4: 32 | B4: 46071 | C4: 799.5 | D4: ULRICH TREVELYAN | E4: Trevelyan | F4: JAN-2026 | G4: D | H4: FAM-009 BELHADJ-TREVELYAN, FAM-053 TREVELYAN | I4: several families fit: FAM-009 (surname TREVELYAN); FAM-053 (surname TREVELYAN) | J4: n/a
A5: 78 | B5: 46143 | C5: 592 | D5: MARGIT PELLETIER | E5: 2025-627 | F5: AUT-2025 | G5: D | H5: FAM-042 NAKASHIMA-PELLETIER, FAM-045 PELLETIER | I5: several families fit: FAM-042 (surname PELLETIER); FAM-045 (surname PELLETIER) | J5: n/a
A6: 81 | B6: 46170 | C6: 592 | D6: MARGIT PELLETIER | E6: Pelletier 2nd | F6: JAN-2026 | G6: D | H6: FAM-042 NAKASHIMA-PELLETIER, FAM-045 PELLETIER | I6: several families fit: FAM-042 (surname PELLETIER); FAM-045 (surname PELLETIER) | J6: n/a
A7: 29 | B7: 46070 | C7: 434.5 | D7: KATRIN BEAUCHAMP | E7: 2026-008 | F7: JAN-2026 | G7: D | H7: FAM-008 BELHADJ, FAM-045 PELLETIER | I7: reference 2026-008 is shared by FAM-008, FAM-045 | J7: n/a
A8: 36 | B8: 46077 | C8: 434.5 | D8: GENEVIEVE HOLLINGWORTH | E8: 2026-024 | F8: JAN-2026 | G8: X | H8: FAM-032 HOLLINGWORTH, FAM-033 IBARRA | I8: reference 2026-024 points to FAM-033 but the memo names FAM-032 — parent may have typed the wrong invoice number | J8: n/a
A9: 49 | B9: 46103 | C9: 434.5 | D9: YOLANDE ACHTERBERG | E9: Achterberg | F9: JAN-2026 | G9: D | H9: FAM-002 ACHTERBERG, FAM-003 ACHTERBERG-MARCHETTI | I9: several families fit: FAM-002 (surname ACHTERBERG); FAM-003 (surname ACHTERBERG) | J9: n/a
A10: 67 | B10: 46133 | C10: 434.5 | D10: MARGIT BELHADJ-TREVELYA | E10: 2026-003 | F10: JAN-2026 | G10: X | H10: FAM-008 BELHADJ, FAM-009 BELHADJ-TREVELYAN, FAM-042 NAKASHIMA-PELLETIER | I10: reference 2026-003 points to FAM-042 but the memo names FAM-008, FAM-009 — parent may have typed the wrong invoice number | J10: n/a
A11: 45 | B11: 46092 | C11: -409.5 | D11: REFUND | E11: withdrawal refund | F11: JAN-2026 | G11: D | I11: no roster surname or child name (from the bank-sheet note, not the memo) | J11: n/a
A12: 68 | B12: 46133 | C12: 347 | D12: TOVE CHIDOZIE | E12: CHIDOZIE FRENCH SCHOO | F12: JAN-2026 | G12: C | H12: FAM-017 CHIDOZIE | I12: surname CHIDOZIE — chosen over FAM-016 because only this family is billed this term | J12: half of expected | K12: 694
A13: 80 | B13: 46168 | C13: 347 | D13: TOVE CHIDOZIE | E13: Chidozie | F13: JAN-2026 | G13: C | H13: FAM-017 CHIDOZIE | I13: surname CHIDOZIE — chosen over FAM-016 because only this family is billed this term | J13: half of expected | K13: 694
